Workbook

Sheet DCF
A1: OPAL Fuels
A2: DCF Model
A3: $ in Thousands
B5: ASSUMPTIONS
B6: Discount Rate | C6: 0.1
B7: Perpetual Growth Rate | C7: 0.03
B8: EV/EBITDA Mulltiple | C8: 7
B9: Current Price | C9: 2.38
B10: Shares Outstanding | C10: 28996177
B12: Terminal Value | D12: PV
B13: Perpetual Growth | C13: =(K52*(1+C7))/(C6-C7) -> 2056929.1 | D13: =PV($C$6,5,,-C13,0) -> 1277191.2
B14: EV/EBITDA | C14: =K28*C8 -> 1584269.4 | D14: =PV($C$6,5,,-C14,0) -> 983706.65
B16: Valuation | C16: Ent Value | D16: Price
B17: Perpetual Growth | C17: =XNPV($C$6,$G$52:$K$52,$G$23:$K$23)+D13 -> 1502686.7 | D17: =C17*1000/C10 -> 51.823615
B18: EV/EBITDA | C18: =XNPV($C$6,$G$52:$K$52,$G$23:$K$23)+D14 -> 1209202.2 | D18: =C18*1000/C10 -> 41.702126
B21: FINANCIALS
C22: ACTUAL | D22: ACTUAL | E22: ACTUAL | F22: ACTUAL | G22: FORECAST | H22: FORECAST | I22: FORECAST | J22: FORECAST | K22: FORECAST
C23: 44561 | D23: 44926 | E23: 45291 | F23: 45657 | G23: =EDATE(F23,12) -> 46022 | H23: =EDATE(G23,12) -> 46387 | I23: =EDATE(H23,12) -> 46752 | J23: =EDATE(I23,12) -> 47118 | K23: =EDATE(J23,12) -> 47483 | L23: Notes
B25: Total Revenue | C25: =SUMIFS('Income Statement'!$D:$D,'Income Statement'!$B:$B,DCF!$B25,'Income Statement'!$C:$C,DCF!C$23)/1000 -> 166124 | D25: =SUMIFS('Income Statement'!$D:$D,'Income Statement'!$B:$B,DCF!$B25,'Income Statement'!$C:$C,DCF!D$23)/1000 -> 235531 | E25: =SUMIFS('Income Statement'!$D:$D,'Income Statement'!$B:$B,DCF!$B25,'Income Statement'!$C:$C,DCF!E$23)/1000 -> 256108 | F25: =SUMIFS('Income Statement'!$D:$D,'Income Statement'!$B:$B,DCF!$B25,'Income Statement'!$C:$C,DCF!F$23)/1000 -> 299972 | G25: 365000 | H25: 450160 | I25: 529710 | J25: 572210 | K25: 595590
D26: =D25/C25-1 -> 0.41780236 | E26: =E25/D25-1 -> 0.087364296 | F26: =F25/E25-1 -> 0.17127149 | G26: =G25/F25-1 -> 0.21678023 | H26: =H25/G25-1 -> 0.23331507 | I26: =I25/H25-1 -> 0.17671495 | J26: =J25/I25-1 -> 0.08023258 | K26: =K25/J25-1 -> 0.040859125
B28: Adjusted EBITDA | C28: =SUMIFS('Income Statement'!$D:$D,'Income Statement'!$B:$B,DCF!$B28,'Income Statement'!$C:$C,DCF!C$23)/1000 -> 0 | D28: 53401 | E28: 51950 | F28: 90005 | G28: =G25*G29 -> 109500 | H28: =H25*H29 -> 144051.2 | I28: =I25*I29 -> 185398.5 | J28: =J25*J29 -> 211717.7 | K28: =K25*K29 -> 226324.2
B29: EBITDA % | C29: =C28/C25 -> 0 | D29: =D28/D25 -> 0.22672599 | E29: =E28/E25 -> 0.20284411 | F29: =F28/F25 -> 0.30004467 | G29: 0.3 | H29: 0.32 | I29: 0.35 | J29: 0.37 | K29: 0.38
B31: Tax Provision | C31: =SUMIFS('Income Statement'!$D:$D,'Income Statement'!$B:$B,DCF!$B31,'Income Statement'!$C:$C,DCF!C$23)/1000 -> 0 | D31: =SUMIFS('Income Statement'!$D:$D,'Income Statement'!$B:$B,DCF!$B31,'Income Statement'!$C:$C,DCF!D$23)/1000 -> 0 | E31: =SUMIFS('Income Statement'!$D:$D,'Income Statement'!$B:$B,DCF!$B31,'Income Statement'!$C:$C,DCF!E$23)/1000 -> 0 | F31: =SUMIFS('Income Statement'!$D:$D,'Income Statement'!$B:$B,DCF!$B31,'Income Statement'!$C:$C,DCF!F$23)/1000 -> -8906 | G31: =G28*G32 -> 0 | H31: =H28*H32 -> 0 | I31: =I28*I32 -> 0 | J31: =J28*J32 -> 0 | K31: =K28*K32 -> 0
B32: Tax Rate % | C32: =C31/C28 -> #DIV/0! | D32: =D31/D28 -> 0 | E32: =E31/E28 -> 0 | F32: =F31/F28 -> -0.098950058 | G32: 0 | H32: 0 | I32: 0 | J32: 0 | K32: 0
B34: Net Working Capital
B35: Current Assets
B36: Accounts Receivable | C36: =SUMIFS('Balance Sheet'!$D:$D,'Balance Sheet'!$B:$B,DCF!$B36,'Balance Sheet'!$C:$C,DCF!C$23)/1000 -> 25391 | D36: =SUMIFS('Balance Sheet'!$D:$D,'Balance Sheet'!$B:$B,DCF!$B36,'Balance Sheet'!$C:$C,DCF!D$23)/1000 -> 31083 | E36: =SUMIFS('Balance Sheet'!$D:$D,'Balance Sheet'!$B:$B,DCF!$B36,'Balance Sheet'!$C:$C,DCF!E$23)/1000 -> 27623 | F36: =SUMIFS('Balance Sheet'!$D:$D,'Balance Sheet'!$B:$B,DCF!$B36,'Balance Sheet'!$C:$C,DCF!F$23)/1000 -> 32013
B37: Inventory | C37: =SUMIFS('Balance Sheet'!$D:$D,'Balance Sheet'!$B:$B,DCF!$B37,'Balance Sheet'!$C:$C,DCF!C$23)/1000 -> 5143 | D37: =SUMIFS('Balance Sheet'!$D:$D,'Balance Sheet'!$B:$B,DCF!$B37,'Balance Sheet'!$C:$C,DCF!D$23)/1000 -> 7311 | E37: =SUMIFS('Balance Sheet'!$D:$D,'Balance Sheet'!$B:$B,DCF!$B37,'Balance Sheet'!$C:$C,DCF!E$23)/1000 -> 10191 | F37: =SUMIFS('Balance Sheet'!$D:$D,'Balance Sheet'!$B:$B,DCF!$B37,'Balance Sheet'!$C:$C,DCF!F$23)/1000 -> 10294
B39: Current Liabilities
B40: Payables And Accrued Expenses | C40: =SUMIFS('Balance Sheet'!$D:$D,'Balance Sheet'!$B:$B,DCF!$B40,'Balance Sheet'!$C:$C,DCF!C$23)/1000 -> 35114 | D40: =SUMIFS('Balance Sheet'!$D:$D,'Balance Sheet'!$B:$B,DCF!$B40,'Balance Sheet'!$C:$C,DCF!D$23)/1000 -> 57819 | E40: =SUMIFS('Balance Sheet'!$D:$D,'Balance Sheet'!$B:$B,DCF!$B40,'Balance Sheet'!$C:$C,DCF!E$23)/1000 -> 63879 | F40: =SUMIFS('Balance Sheet'!$D:$D,'Balance Sheet'!$B:$B,DCF!$B40,'Balance Sheet'!$C:$C,DCF!F$23)/1000 -> 76511
B41: Current Provisions | C41: =SUMIFS('Balance Sheet'!$D:$D,'Balance Sheet'!$B:$B,DCF!$B41,'Balance Sheet'!$C:$C,DCF!C$23)/1000 -> 831 | D41: =SUMIFS('Balance Sheet'!$D:$D,'Balance Sheet'!$B:$B,DCF!$B41,'Balance Sheet'!$C:$C,DCF!D$23)/1000 -> 1296 | E41: =SUMIFS('Balance Sheet'!$D:$D,'Balance Sheet'!$B:$B,DCF!$B41,'Balance Sheet'!$C:$C,DCF!E$23)/1000 -> 1812 | F41: =SUMIFS('Balance Sheet'!$D:$D,'Balance Sheet'!$B:$B,DCF!$B41,'Balance Sheet'!$C:$C,DCF!F$23)/1000 -> 2804
B42: Other Current Liabilities | C42: =SUMIFS('Balance Sheet'!$D:$D,'Balance Sheet'!$B:$B,DCF!$B42,'Balance Sheet'!$C:$C,DCF!C$23)/1000 -> 1366 | D42: =SUMIFS('Balance Sheet'!$D:$D,'Balance Sheet'!$B:$B,DCF!$B42,'Balance Sheet'!$C:$C,DCF!D$23)/1000 -> 5681 | E42: =SUMIFS('Balance Sheet'!$D:$D,'Balance Sheet'!$B:$B,DCF!$B42,'Balance Sheet'!$C:$C,DCF!E$23)/1000 -> 92 | F42: =SUMIFS('Balance Sheet'!$D:$D,'Balance Sheet'!$B:$B,DCF!$B42,'Balance Sheet'!$C:$C,DCF!F$23)/1000 -> 1604
B44: Net working Capital | C44: =SUM(C36:C37)-SUM(C40:C42) -> -6777 | D44: =SUM(D36:D37)-SUM(D40:D42) -> -26402 | E44: =SUM(E36:E37)-SUM(E40:E42) -> -27969 | F44: =SUM(F36:F37)-SUM(F40:F42) -> -38612 | G44: =G25*G45 -> -47450 | H44: =H25*H45 -> -58520.8 | I44: =I25*I45 -> -63565.2 | J44: =J25*J45 -> -68665.2 | K44: =K25*K45 -> -71470.8
B45: % of Revenue | C45: =C44/C25 -> -0.040794828 | D45: =D44/D25 -> -0.11209565 | E45: =E44/E25 -> -0.10920783 | F45: =F44/F25 -> -0.12871868 | G45: -0.13 | H45: -0.13 | I45: -0.12 | J45: -0.12 | K45: -0.12 | L45: Assuming efficiency gains aren't realized until 2027.
B47: Change in NWC | D47: =D44-C44 -> -19625 | E47: =E44-D44 -> -1567 | F47: =F44-E44 -> -10643 | G47: =G44-F44 -> -8838 | H47: =H44-G44 -> -11070.8 | I47: =I44-H44 -> -5044.4 | J47: =J44-I44 -> -5100 | K47: =K44-J44 -> -2805.6
B49: Capital Expenditure | C49: =SUMIFS('Cash Flow'!$D:$D,'Cash Flow'!$B:$B,DCF!$B49,'Cash Flow'!$C:$C,DCF!C$23)/1000 -> -89646 | D49: =SUMIFS('Cash Flow'!$D:$D,'Cash Flow'!$B:$B,DCF!$B49,'Cash Flow'!$C:$C,DCF!D$23)/1000 -> -131410 | E49: =SUMIFS('Cash Flow'!$D:$D,'Cash Flow'!$B:$B,DCF!$B49,'Cash Flow'!$C:$C,DCF!E$23)/1000 -> -113826 | F49: =SUMIFS('Cash Flow'!$D:$D,'Cash Flow'!$B:$B,DCF!$B49,'Cash Flow'!$C:$C,DCF!F$23)/1000 -> -127239 | G49: =G25*G50 -> -109500 | H49: =H25*H50 -> -135048 | I49: =I25*I50 -> -158913 | J49: =J25*J50 -> -114442 | K49: =K25*K50 -> -89338.5
B50: % of Revenue | C50: =C49/C25 -> -0.53963305 | D50: =D49/D25 -> -0.5579308 | E50: =E49/E25 -> -0.44444531 | F50: =F49/F25 -> -0.42416959 | G50: -0.3 | H50: -0.3 | I50: -0.3 | J50: -0.2 | K50: -0.15 | L50: 25 - 27: Ongoing projects. 28 - 29 Winddown
B52: UFCF | C52: =C28-C31-C47+C49 -> -89646 | D52: =D28-D31-D47+D49 -> -58384 | E52: =E28-E31-E47+E49 -> -60309 | F52: =F28-F31-F47+F49 -> -17685 | G52: =G28-G31-G47+G49 -> 8838 | H52: =H28-H31-H47+H49 -> 20074 | I52: =I28-I31-I47+I49 -> 31529.9 | J52: =J28-J31-J47+J49 -> 102375.7 | K52: =K28-K31-K47+K49 -> 139791.3

Sheet Income Statement
B1: measure | C1: year | D1: value
A2: 0 | B2: Tax Effect Of Unusual Items | C2: 45657 | D2: -88200
A3: 1 | B3: Tax Rate For Calcs | C3: 45657 | D3: 0.21
A4: 2 | B4: Normalized EBITDA | C4: 45657 | D4: 41374000
A5: 3 | B5: Total Unusual Items | C5: 45657 | D5: -420000
A6: 4 | B6: Total Unusual Items Excluding Goodwill | C6: 45657 | D6: -420000
A7: 5 | B7: Net Income From Continuing Operation Net Minority Interest | C7: 45657 | D7: 11031000
A8: 6 | B8: Reconciled Depreciation | C8: 45657 | D8: 18129000
A9: 7 | B9: Reconciled Cost Of Revenue | C9: 45657 | D9: 199607000
A10: 8 | B10: EBITDA | C10: 45657 | D10: 40954000
A11: 9 | B11: EBIT | C11: 45657 | D11: 22825000
A12: 10 | B12: Net Interest Income | C12: 45657 | D12: -19610000
A13: 11 | B13: Interest Expense | C13: 45657 | D13: 17406000
... A34: 32 | B34: Special Income Charges | C34: 45657 | D34: -2016000
A35: 33 | B35: Gain On Sale Of Ppe | C35: 45657
A36: 34 | B36: Gain On Sale Of Business | C36: 45657 | D36: 0
A37: 35 | B37: Other Special Charges | C37: 45657 | D37: 19109000
A38: 36 | B38: Write Off | C38: 45657 | D38: 2016000
A39: 37 | B39: Impairment Of Capital Assets | C39: 45657
A40: 38 | B40: Restructuring And Mergern Acquisition | C40: 45657
A41: 39 | B41: Earnings From Equity Interest | C41: 45657 | D41: 13235000
A42: 40 | B42: Gain On Sale Of Security | C42: 45657 | D42: 1596000
A43: 41 | B43: Net Non Operating Interest Income Expense | C43: 45657 | D43: -19610000
A44: 42 | B44: Total Other Finance Cost | C44: 45657 | D44: 4125000
A45: 43 | B45: Interest Expense Non Operating | C45: 45657 | D45: 17406000
A46: 44 | B46: Interest Income Non Operating | C46: 45657 | D46: 1921000
A47: 45 | B47: Operating Income | C47: 45657 | D47: 10003000
A48: 46 | B48: Operating Expense | C48: 45657 | D48: 90118000
A49: 47 | B49: Other Operating Expenses | C49: 45657 | D49: 19109000
A50: 48 | B50: Depreciation Amortization Depletion Income Statement | C50: 45657 | D50: 17885000
A51: 49 | B51: Depreciation And Amortization In Income Statement | C51: 45657 | D51: 17885000
A52: 50 | B52: Research And Development | C52: 45657
A53: 51 | B53: Selling General And Administration | C53: 45657 | D53: 53124000
A54: 52 | B54: Gross Profit | C54: 45657 | D54: 100121000
A55: 53 | B55: Cost Of Revenue | C55: 45657 | D55: 199851000
A56: 54 | B56: Total Revenue | C56: 45657 | D56: 299972000
A57: 55 | B57: Operating Revenue | C57: 45657 | D57: 299972000
A58: 56 | B58: Tax Effect Of Unusual Items | C58: 45291 | D58: 0
A59: 57 | B59: Tax Rate For Calcs | C59: 45291 | D59: 0
A60: 58 | B60: Normalized EBITDA | C60: 45291 | D60: 23049000
...

Sheet Cash Flow
B1: measure | C1: year | D1: value
A2: 0 | B2: Free Cash Flow | C2: 45657 | D2: -94206000
A3: 1 | B3: Repurchase Of Capital Stock | C3: 45657 | D3: 0
A4: 2 | B4: Repayment Of Debt | C4: 45657 | D4: -1621000
A5: 3 | B5: Issuance Of Debt | C5: 45657 | D5: 100000000
A6: 4 | B6: Issuance Of Capital Stock | C6: 45657 | D6: 170000
A7: 5 | B7: Capital Expenditure | C7: 45657 | D7: -127239000
A8: 6 | B8: Interest Paid Supplemental Data | C8: 45657 | D8: 22907000
A9: 7 | B9: Income Tax Paid Supplemental Data | C9: 45657 | D9: 20000
A10: 8 | B10: End Cash Position | C10: 45657 | D10: 29228000
A11: 9 | B11: Beginning Cash Position | C11: 45657 | D11: 47242000
A12: 10 | B12: Changes In Cash | C12: 45657 | D12: -18014000
A13: 11 | B13: Financing Cash Flow | C13: 45657 | D13: 83504000
... A15: 13 | B15: Net Other Financing Charges | C15: 45657 | D15: -1959000
A16: 14 | B16: Interest Paid Cff | C16: 45657
A17: 15 | B17: Proceeds From Stock Option Exercised | C17: 45657
A18: 16 | B18: Cash Dividends Paid | C18: 45657 | D18: -13086000
A19: 17 | B19: Preferred Stock Dividend Paid | C19: 45657 | D19: -13086000
A20: 18 | B20: Common Stock Dividend Paid | C20: 45657
A21: 19 | B21: Net Preferred Stock Issuance | C21: 45657
A22: 20 | B22: Preferred Stock Issuance | C22: 45657
A23: 21 | B23: Net Common Stock Issuance | C23: 45657 | D23: 170000
A24: 22 | B24: Common Stock Payments | C24: 45657 | D24: 0
A25: 23 | B25: Common Stock Issuance | C25: 45657 | D25: 170000
A26: 24 | B26: Net Issuance Payments Of Debt | C26: 45657 | D26: 98379000
A27: 25 | B27: Net Short Term Debt Issuance | C27: 45657 | D27: 0
A28: 26 | B28: Short Term Debt Payments | C28: 45657 | D28: 0
A29: 27 | B29: Short Term Debt Issuance | C29: 45657
A30: 28 | B30: Net Long Term Debt Issuance | C30: 45657 | D30: 98379000
A31: 29 | B31: Long Term Debt Payments | C31: 45657 | D31: -1621000
A32: 30 | B32: Long Term Debt Issuance | C32: 45657 | D32: 100000000
A33: 31 | B33: Investing Cash Flow | C33: 45657 | D33: -134551000
A34: 32 | B34: Cash Flow From Continuing Investing Activities | C34: 45657 | D34: -134551000
A35: 33 | B35: Net Other Investing Changes | C35: 45657 | D35: -750000
A36: 34 | B36: Interest Received Cfi | C36: 45657
A37: 35 | B37: Dividends Received Cfi | C37: 45657 | D37: 4305000
A38: 36 | B38: Net Investment Purchase And Sale | C38: 45657 | D38: 9875000
A39: 37 | B39: Sale Of Investment | C39: 45657 | D39: 9875000
A40: 38 | B40: Purchase Of Investment | C40: 45657
A41: 39 | B41: Net Business Purchase And Sale | C41: 45657 | D41: -21570000
...

Sheet Balance Sheet
B1: measure | C1: year | D1: value
A2: 0 | B2: Treasury Shares Number | C2: 45657 | D2: 1635783
A3: 1 | B3: Ordinary Shares Number | C3: 45657 | D3: 28429477
A4: 2 | B4: Share Issued | C4: 45657 | D4: 30065260
A5: 3 | B5: Net Debt | C5: 45657 | D5: 273314000
A6: 4 | B6: Total Debt | C6: 45657 | D6: 310559000
A7: 5 | B7: Tangible Book Value | C7: 45657 | D7: -208819000
A8: 6 | B8: Invested Capital | C8: 45657 | D8: 149175000
A9: 7 | B9: Working Capital | C9: 45657 | D9: 13592000
A10: 8 | B10: Net Tangible Assets | C10: 45657 | D10: -208819000
A11: 9 | B11: Capital Lease Obligations | C11: 45657 | D11: 12935000
A12: 10 | B12: Common Stock Equity | C12: 45657 | D12: -148449000
A13: 11 | B13: Preferred Stock Equity | C13: 45657
A14: 12 | B14: Total Capitalization | C14: 45657 | D14: 136554000
A15: 13 | B15: Total Equity Gross Minority Interest | C15: 45657 | D15: 465032000
A16: 14 | B16: Minority Interest | C16: 45657 | D16: 613481000
A17: 15 | B17: Stockholders Equity | C17: 45657 | D17: -148449000
A18: 16 | B18: Gains Losses Not Affecting Retained Earnings | C18: 45657 | D18: 152000
A19: 17 | B19: Other Equity Adjustments | C19: 45657 | D19: 152000
A20: 18 | B20: Treasury Stock | C20: 45657 | D20: 11614000
A21: 19 | B21: Retained Earnings | C21: 45657 | D21: -137004000
A22: 20 | B22: Additional Paid In Capital | C22: 45657 | D22: 0
A23: 21 | B23: Capital Stock | C23: 45657 | D23: 17000
A24: 22 | B24: Common Stock | C24: 45657 | D24: 17000
A25: 23 | B25: Preferred Stock | C25: 45657
A26: 24 | B26: Total Partnership Capital | C26: 45657
A27: 25 | B27: Limited Partnership Capital | C27: 45657
A28: 26 | B28: Total Liabilities Net Minority Interest | C28: 45657 | D28: 416045000
A29: 27 | B29: Total Non Current Liabilities Net Minority Interest | C29: 45657 | D29: 312449000
A30: 28 | B30: Other Non Current Liabilities | C30: 45657 | D30: 10146000
A31: 29 | B31: Preferred Securities Outside Stock Equity | C31: 45657
A32: 30 | B32: Derivative Product Liabilities | C32: 45657 | D32: 63000
A33: 31 | B33: Long Term Debt And Capital Lease Obligation | C33: 45657 | D33: 297158000
A34: 32 | B34: Long Term Capital Lease Obligation | C34: 45657 | D34: 12155000
A35: 33 | B35: Long Term Debt | C35: 45657 | D35: 285003000
A36: 34 | B36: Long Term Provisions | C36: 45657 | D36: 5082000
A37: 35 | B37: Current Liabilities | C37: 45657 | D37: 103596000
A38: 36 | B38: Other Current Liabilities | C38: 45657 | D38: 1604000
A39: 37 | B39: Current Deferred Liabilities | C39: 45657 | D39: 9276000
A40: 38 | B40: Current Deferred Revenue | C40: 45657 | D40: 9276000
...
